2021-10-03 13:07:13,631 - instabot version: 0.117.0 (bot) - INFO - Instabot version: 0.117.0 Started
2021-10-03 13:07:13,632 - instabot version: 0.117.0 (bot) - DEBUG - Bot imported from /home/nacreousdawn596/.local/lib/python3.8/site-packages/instabot/bot/bot.py
2021-10-03 13:07:13,633 - instabot version: 0.117.0 (api_login) - INFO - Not yet logged in starting: PRE-LOGIN FLOW!
2021-10-03 13:07:14,258 - instabot version: 0.117.0 (api) - DEBUG - POST to endpoint: accounts/get_prefill_candidates/ returned response: <Response [429]>
2021-10-03 13:07:14,258 - instabot version: 0.117.0 (api) - DEBUG - Responsecode indicates error; response content: b'{"message":"Please wait a few minutes before you try again.","status":"fail"}'
2021-10-03 13:07:14,258 - instabot version: 0.117.0 (api) - ERROR - Request returns 429 error!
2021-10-03 13:07:14,259 - instabot version: 0.117.0 (api) - WARNING - That means 'too many requests'. I'll go to sleep for 5 minutes.
2021-10-03 13:12:24,371 - instabot version: 0.117.0 (api) - WARNING - HTTPSConnectionPool(host='i.instagram.com', port=443): Max retries exceeded with url: /api/v1/accounts/get_prefill_candidates/ (Caused by NewConnectionError('<urllib3.connection.VerifiedHTTPSConnection object at 0x7fea56e4ed30>: Failed to establish a new connection: [Errno -3] Temporary failure in name resolution'))
2021-10-03 13:12:34,387 - instabot version: 0.117.0 (api) - WARNING - HTTPSConnectionPool(host='i.instagram.com', port=443): Max retries exceeded with url: /api/v1/qe/sync/ (Caused by NewConnectionError('<urllib3.connection.VerifiedHTTPSConnection object at 0x7fea56e60250>: Failed to establish a new connection: [Errno -3] Temporary failure in name resolution'))
2021-10-03 13:12:36,270 - instabot version: 0.117.0 (api) - WARNING - HTTPSConnectionPool(host='i.instagram.com', port=443): Max retries exceeded with url: /api/v1/launcher/sync/ (Caused by NewConnectionError('<urllib3.connection.VerifiedHTTPSConnection object at 0x7fea56e60280>: Failed to establish a new connection: [Errno -3] Temporary failure in name resolution'))
2021-10-03 13:12:36,289 - instabot version: 0.117.0 (api) - WARNING - HTTPSConnectionPool(host='i.instagram.com', port=443): Max retries exceeded with url: /api/v1/accounts/contact_point_prefill/ (Caused by NewConnectionError('<urllib3.connection.VerifiedHTTPSConnection object at 0x7fea56e60460>: Failed to establish a new connection: [Errno -3] Temporary failure in name resolution'))
